Workbook

Sheet Max capacities
B1: Baseline maximum capacities
D3: Total area (km2) | E3: Solar pv (MW) | F3: Wind (MW) | G3: Geothermal (MW)
C4: ATG | D4: 281 | E4: 370 | F4: 100 | G4: --
C5: BRB | D5: 432 | E5: 570 | F5: 150 | G5: --
C6: DMA | D6: 750 | E6: 1000 | F6: 300 | G6: 15
C7: GLP | D7: 1628 | E7: 2200 | F7: 600 | G7: 50
C8: GRD | D8: 349 | E8: 470 | F8: 120 | G8: 20
C9: LCA | D9: 617 | E9: 800 | F9: 200 | G9: 30
C10: MSR | D10: 102 | E10: 133 | F10: 30 | G10: 5
C11: MTQ | D11: 1128 | E11: 1500 | F11: 400 | G11: 50
C12: SKN | D12: 261 | E12: 350 | F12: 100 | G12: 30
C13: SVG | D13: 345 | E13: 460 | F13: 120 | G13: 15

Sheet 0. Current system
B1: Current system | E1: Extendable_baseline_final
B2: 45700
F3: lcoe | G3: 183 | H3: $/MWh
F4: Country
F5: ATG | G5: 202.11973
F6: BRB | G6: 184.54548
F7: DMA | G7: 128.86779
F8: GLP | G8: 171.72627
F9: GRD | G9: 201.66069
F10: LCA | G10: 201.48525
F11: MSR | G11: 191.2042
F12: MTQ | G12: 185.70412
F13: SKN | G13: 197.88513
F14: SVG | G14: 157.20649
B16: Capacity [MW]
B17: Technology | C17: biomass | D17: coal | E17: diesel | F17: geothermal | G17: hydro | H17: solar pv | I17: wind
B18: Country
B19: ATG | C19: NaN | D19: NaN | E19: 67.2 | F19: NaN | G19: NaN | H19: 6 | I19: 0
B20: BRB | C20: 0 | D20: NaN | E20: 186 | F20: NaN | G20: NaN | H20: 108 | I20: 0
B21: DMA | C21: NaN | D21: NaN | E21: 13.4 | F21: 0 | G21: 6.6 | H21: 0 | I21: 0
B22: GLP | C22: 3.7 | D22: 0 | E22: 262.8141 | F22: 14.7 | G22: 10.5 | H22: 70 | I22: 22.1
B23: GRD | C23: NaN | D23: NaN | E23: 40.2 | F23: 0 | G23: 0 | H23: 4 | I23: 0
B24: LCA | C24: NaN | D24: NaN | E24: 73 | F24: 0 | G24: NaN | H24: 8 | I24: 0
B25: MSR | C25: NaN | D25: NaN | E25: 2.54 | F25: 0 | G25: NaN | H25: 1 | I25: 0
B26: MTQ | C26: 41.4 | D26: NaN | E26: 233.381 | F26: 0 | G26: NaN | H26: 76.7 | I26: 13
B27: SKN | C27: NaN | D27: NaN | E27: 40.9465 | F27: 0 | G27: NaN | H27: 1.5 | I27: 2.2
B28: SVG | C28: NaN | D28: NaN | E28: 22.3376 | F28: 0 | G28: 5.6 | H28: 1.8 | I28: 0
B29: Generation [GWh] | J29: solar pv fraction | K29: wind fraction | L29: CO2 emissions [ktCO2]
B30: Technology | C30: biomass | D30: coal | E30: diesel | F30: geothermal | G30: hydro | H30: solar pv | I30: wind
B31: Country
B32: ATG | C32: NaN | D32: NaN | E32: 426.32025 | F32: NaN | G32: NaN | H32: 10.695792 | I32: 0 | J32: =H32/(SUM($C32:$I32)) -> 0.024474598 | K32: =I32/(SUM($C32:$I32)) -> 0 | L32: =E32*$E$57 -> 281.37136
B33: BRB | C33: 0 | D33: NaN | E33: 1011.1778 | F33: NaN | G33: NaN | H33: 190.74431 | I33: 0 | J33: =H33/(SUM($C33:$I33)) -> 0.15869939 | K33: =I33/(SUM($C33:$I33)) -> 0 | L33: =E33*$E$57 -> 667.37734
B34: DMA | C34: NaN | D34: NaN | E34: 69.6649 | F34: 0 | G34: 57.816 | H34: 0 | I34: 0 | J34: =H34/(SUM($C34:$I34)) -> 0 | K34: =I34/(SUM($C34:$I34)) -> 0 | L34: =E34*$E$57 -> 45.978834
B35: GLP | C35: 32.412 | D35: 0 | E35: 1524.4082 | F35: 128.772 | G35: 91.98 | H35: 124.5307 | I35: 101.06732 | J35: =H35/(SUM($C35:$I35)) -> 0.062166809 | K35: =I35/(SUM($C35:$I35)) -> 0.050453687 | L35: =E35*$E$57 -> 1006.1094
B36: GRD | C36: NaN | D36: NaN | E36: 257.13632 | F36: 0 | G36: 0 | H36: 6.88238 | I36: 0 | J36: =H36/(SUM($C36:$I36)) -> 0.026067775 | K36: =I36/(SUM($C36:$I36)) -> 0 | L36: =E36*$E$57 -> 169.70997
B37: LCA | C37: NaN | D37: NaN | E37: 459.27306 | F37: 0 | G37: NaN | H37: 14.166344 | I37: 0 | J37: =H37/(SUM($C37:$I37)) -> 0.029922191 | K37: =I37/(SUM($C37:$I37)) -> 0 | L37: =E37*$E$57 -> 303.12022
B38: MSR | C38: NaN | D38: NaN | E38: 14.612479 | F38: 0 | G38: NaN | H38: 1.778041 | I38: 0 | J38: =H38/(SUM($C38:$I38)) -> 0.10847984 | K38: =I38/(SUM($C38:$I38)) -> 0 | L38: =E38*$E$57 -> 9.6442361
B39: MTQ | C39: 362.664 | D39: NaN | E39: 1257.4897 | F39: 0 | G39: NaN | H39: 136.52347 | I39: 64.396124 | J39: =H39/(SUM($C39:$I39)) -> 0.074968684 | K39: =I39/(SUM($C39:$I39)) -> 0.035361632 | L39: =E39*$E$57 -> 829.94321
B40: SKN | C40: NaN | D40: NaN | E40: 260.98489 | F40: 0 | G40: NaN | H40: 2.657442 | I40: 9.540513 | J40: =H40/(SUM($C40:$I40)) -> 0.0097277044 | K40: =I40/(SUM($C40:$I40)) -> 0.034923543 | L40: =E40*$E$57 -> 172.25003
B41: SVG | C41: NaN | D41: NaN | E41: 129.89017 | F41: 0 | G41: 49.056 | H41: 3.170434 | I41: 0 | J41: =H41/(SUM($C41:$I41)) -> 0.017408814 | K41: =I41/(SUM($C41:$I41)) -> 0 | L41: =E41*$E$57 -> 85.72751
...

Sheet 1. Diesel, no storage
B1: Baseline | G1: Extendable_newbaseline_higher-geothermal-cost_must-run-VRE_max-geo | P1: Less solar and wind available | V1: Extendable_half-wind-solar-cap | W1: Higher geothermal cost as baseline | AD1: Higher fuel cost | AI1: Extendable_newbaseline_higher-geothermal-cost_must-run-VRE_max-geo_high-fuel | AR1: Lower VRE | AY1: Extendable_quarter-wind-solar-cap
B2: 45904 | C2: Use new baseline with "double" solar and wind | J2: Must-run VRE | P2: 04.09.2025 | X2: Must-run VRE | AD2: 04.09.2025 | AE2: Baseline solar and wind | AL2: Must-run VRE | AR2: 45904 | AS2: Baseline solar and wind | AZ2: Must-run VRE
C3: Higher geothermal cost as baseline | F3: LCOE, region | G3: 118.9 | H3: =(G3-'0. Current system'!$G3)/'0. Current system'!$G3 -> -0.35027322 | J3: Max 90% geothermal | Q3: Higher geothermal cost as baseline | T3: LCOE, region | U3: 122 | V3: =(U3-'0. Current system'!$G3)/'0. Current system'!$G3 -> -0.33333333 | W3: =(U3-$G3)/$G3 -> 0.02607233 | X3: Max 90% geothermal | AE3: Higher geothermal cost as baseline | AH3: LCOE, region | AI3: 135.9 | AJ3: =(AI3-'0. Current system'!$G3)/'0. Current system'!$G3 -> -0.25737705 | AK3: =(AI3-$G3)/$G3 -> 0.14297729 | AL3: Max 90% geothermal | AS3: Higher geothermal cost as baseline | AV3: LCOE, region | AW3: 130 | AX3: $/MWh | AY3: =(AW3-$G3)/$G3 -> 0.093355761 | AZ3: Max 90% geothermal
B4: 1.1 | C4: Take as a new baseline | F4: Country | G4: $/MWh | H4: compared to current system | P4: 1.2 | T4: Country | U4: $/MWh | V4: compared to current system | W4: compared to base | AD4: 1.3 | AH4: Country | AI4: $/MWh | AJ4: compared to current system | AK4: compared to base | AR4: 1.4 | AV4: Country | AX4: compared to current system | AY4: compared to base
F5: ATG | G5: 137.31785 | H5: =(G5-'0. Current system'!$G5)/'0. Current system'!$G5 -> -0.32061137 | L5: =G5*L32 -> 60010.101 | Q5: Half wind and solar max cap | T5: ATG | U5: 137.31785 | V5: =(U5-'0. Current system'!$G5)/'0. Current system'!$G5 -> -0.32061137 | W5: =(U5-$G5)/$G5 -> 0 | Z5: =U5*Z32 -> 60010.101 | AE5: Higher fuel cost | AH5: ATG | AI5: 171.26236 | AJ5: =(AI5-'0. Current system'!$G5)/'0. Current system'!$G5 -> -0.15266879 | AK5: =(AI5-$G5)/$G5 -> 0.24719664 | AN5: =AI5*AN32 -> 74844.396 | AS5: Quarter base VRE max cap | AV5: ATG | AW5: 154.26797 | AX5: =(AW5-'0. Current system'!$G5)/'0. Current system'!$G5 -> -0.23674958 | AY5: =(AW5-$G5)/$G5 -> 0.12343715 | BB5: =AW5*BB32 -> 67417.576
F6: BRB | G6: 123.74759 | H6: =(G6-'0. Current system'!$G6)/'0. Current system'!$G6 -> -0.32944666 | L6: =G6*L33 -> 148734.96 | T6: BRB | U6: 141.49195 | V6: =(U6-'0. Current system'!$G6)/'0. Current system'!$G6 -> -0.23329497 | W6: =(U6-$G6)/$G6 -> 0.14339156 | Z6: =U6*Z33 -> 170062.3 | AH6: BRB | AI6: 149.29863 | AJ6: =(AI6-'0. Current system'!$G6)/'0. Current system'!$G6 -> -0.19099277 | AK6: =(AI6-$G6)/$G6 -> 0.20647707 | AN6: =AI6*AN33 -> 179445.32 | AV6: BRB | AW6: 164.25792 | AX6: =(AW6-'0. Current system'!$G6)/'0. Current system'!$G6 -> -0.10993258 | AY6: =(AW6-$G6)/$G6 -> 0.3273626 | BB6: =AW6*BB33 -> 197425.22
F7: DMA | G7: 111.5797 | H7: =(G7-'0. Current system'!$G7)/'0. Current system'!$G7 -> -0.1341537 | L7: =G7*L34 -> 14224.281 | T7: DMA | U7: 111.5797 | V7: =(U7-'0. Current system'!$G7)/'0. Current system'!$G7 -> -0.1341537 | W7: =(U7-$G7)/$G7 -> 0 | Z7: =U7*Z34 -> 14224.281 | AH7: DMA | AI7: 111.5797 | AJ7: =(AI7-'0. Current system'!$G7)/'0. Current system'!$G7 -> -0.1341537 | AK7: =(AI7-$G7)/$G7 -> 0 | AN7: =AI7*AN34 -> 14224.281 | AV7: DMA | AW7: 111.5797 | AX7: =(AW7-'0. Current system'!$G7)/'0. Current system'!$G7 -> -0.1341537 | AY7: =(AW7-$G7)/$G7 -> 0 | BB7: =AW7*BB34 -> 14224.281
F8: GLP | G8: 116.77275 | H8: =(G8-'0. Current system'!$G8)/'0. Current system'!$G8 -> -0.3200065 | L8: =G8*L35 -> 233915.69 | T8: GLP | U8: 116.77275 | V8: =(U8-'0. Current system'!$G8)/'0. Current system'!$G8 -> -0.3200065 | W8: =(U8-$G8)/$G8 -> 0 | Z8: =U8*Z35 -> 233915.69 | AH8: GLP | AI8: 135.72326 | AJ8: =(AI8-'0. Current system'!$G8)/'0. Current system'!$G8 -> -0.20965348 | AK8: =(AI8-$G8)/$G8 -> 0.16228541 | AN8: =AI8*AN35 -> 271876.79 | AV8: GLP | AW8: 118.11769 | AX8: =(AW8-'0. Current system'!$G8)/'0. Current system'!$G8 -> -0.31217463 | AY8: =(AW8-$G8)/$G8 -> 0.011517576 | BB8: =AW8*BB35 -> 236609.83
F9: GRD | G9: 119.17108 | H9: =(G9-'0. Current system'!$G9)/'0. Current system'!$G9 -> -0.4090515 | L9: =G9*L36 -> 31463.394 | T9: GRD | U9: 119.17108 | V9: =(U9-'0. Current system'!$G9)/'0. Current system'!$G9 -> -0.4090515 | W9: =(U9-$G9)/$G9 -> 0 | Z9: =U9*Z36 -> 31463.394 | AH9: GRD | AI9: 129.77785 | AJ9: =(AI9-'0. Current system'!$G9)/'0. Current system'!$G9 -> -0.35645438 | AK9: =(AI9-$G9)/$G9 -> 0.089004572 | AN9: =AI9*AN36 -> 34263.78 | AV9: GRD | AW9: 119.17108 | AX9: =(AW9-'0. Current system'!$G9)/'0. Current system'!$G9 -> -0.4090515 | AY9: =(AW9-$G9)/$G9 -> 0 | BB9: =AW9*BB36 -> 31463.394
F10: LCA | G10: 118.58893 | H10: =(G10-'0. Current system'!$G10)/'0. Current system'!$G10 -> -0.41142627 | L10: =G10*L37 -> 56144.671 | T10: LCA | U10: 118.58893 | V10: =(U10-'0. Current system'!$G10)/'0. Current system'!$G10 -> -0.41142627 | W10: =(U10-$G10)/$G10 -> 0 | Z10: =U10*Z37 -> 56144.671 | AH10: LCA | AI10: 131.63982 | AJ10: =(AI10-'0. Current system'!$G10)/'0. Current system'!$G10 -> -0.34665285 | AK10: =(AI10-$G10)/$G10 -> 0.1100515 | AN10: =AI10*AN37 -> 62323.476 | AV10: LCA | AW10: 118.58893 | AX10: =(AW10-'0. Current system'!$G10)/'0. Current system'!$G10 -> -0.41142627 | AY10: =(AW10-$G10)/$G10 -> 0 | BB10: =AW10*BB37 -> 56144.671
F11: MSR | G11: 129.22201 | H11: =(G11-'0. Current system'!$G11)/'0. Current system'!$G11 -> -0.32416752 | L11: =G11*L38 -> 2118.0158 | T11: MSR | U11: 129.22201 | V11: =(U11-'0. Current system'!$G11)/'0. Current system'!$G11 -> -0.32416752 | W11: =(U11-$G11)/$G11 -> 0 | Z11: =U11*Z38 -> 2118.0159 | AH11: MSR | AI11: 138.70593 | AJ11: =(AI11-'0. Current system'!$G11)/'0. Current system'!$G11 -> -0.27456653 | AK11: =(AI11-$G11)/$G11 -> 0.073392427 | AN11: =AI11*AN38 -> 2273.4624 | AV11: MSR | AW11: 129.22201 | AX11: =(AW11-'0. Current system'!$G11)/'0. Current system'!$G11 -> -0.32416752 | AY11: =(AW11-$G11)/$G11 -> 0 | BB11: =AW11*BB38 -> 2118.0158
F12: MTQ | G12: 118.7525 | H12: =(G12-'0. Current system'!$G12)/'0. Current system'!$G12 -> -0.36052846 | L12: =G12*L39 -> 216257.01 | T12: MTQ | U12: 118.7525 | V12: =(U12-'0. Current system'!$G12)/'0. Current system'!$G12 -> -0.36052846 | W12: =(U12-$G12)/$G12 -> 0 | Z12: =U12*Z39 -> 216257.01 | AH12: MTQ | AI12: 130.63453 | AJ12: =(AI12-'0. Current system'!$G12)/'0. Current system'!$G12 -> -0.29654483 | AK12: =(AI12-$G12)/$G12 -> 0.10005704 | AN12: =AI12*AN39 -> 237895.05 | AV12: MTQ | AW12: 126.82448 | AX12: =(AW12-'0. Current system'!$G12)/'0. Current system'!$G12 -> -0.31706157 | AY12: =(AW12-$G12)/$G12 -> 0.067973145 | BB12: =AW12*BB39 -> 230956.68
F13: SKN | G13: 122.1881 | H13: =(G13-'0. Current system'!$G13)/'0. Current system'!$G13 -> -0.38253015 | L13: =G13*L40 -> 33379.693 | T13: SKN | U13: 122.1881 | V13: =(U13-'0. Current system'!$G13)/'0. Current system'!$G13 -> -0.38253015 | W13: =(U13-$G13)/$G13 -> 0 | Z13: =U13*Z40 -> 33379.693 | AH13: SKN | AI13: 127.13747 | AJ13: =(AI13-'0. Current system'!$G13)/'0. Current system'!$G13 -> -0.35751882 | AK13: =(AI13-$G13)/$G13 -> 0.040506154 | AN13: =AI13*AN40 -> 34731.776 | AV13: SKN | AW13: 122.1881 | AX13: =(AW13-'0. Current system'!$G13)/'0. Current system'!$G13 -> -0.38253015 | AY13: =(AW13-$G13)/$G13 -> 0 | BB13: =AW13*BB40 -> 33379.693
F14: SVG | G14: 65.909488 | H14: =(G14-'0. Current system'!$G14)/'0. Current system'!$G14 -> -0.58074575 | L14: =G14*L41 -> 12003.212 | T14: SVG | U14: 65.909488 | V14: =(U14-'0. Current system'!$G14)/'0. Current system'!$G14 -> -0.58074575 | W14: =(U14-$G14)/$G14 -> 0 | Z14: =U14*Z41 -> 12003.212 | AH14: SVG | AI14: 65.909488 | AJ14: =(AI14-'0. Current system'!$G14)/'0. Current system'!$G14 -> -0.58074575 | AK14: =(AI14-$G14)/$G14 -> 0 | AN14: =AI14*AN41 -> 12003.212 | AV14: SVG | AW14: 65.909488 | AX14: =(AW14-'0. Current system'!$G14)/'0. Current system'!$G14 -> -0.58074575 | AY14: =(AW14-$G14)/$G14 -> 0 | BB14: =AW14*BB41 -> 12003.212
B16: Capacity [MW] | L16: =SUM(L5:L14)/SUM(L32:L41) -> 118.86376 | P16: Capacity [MW] | Z16: =SUM(Z5:Z14)/SUM(Z32:Z41) -> 122.00022 | AD16: Capacity [MW] | AN16: =SUM(AN5:AN14)/SUM(AN32:AN41) -> 135.86872 | AR16: Capacity [MW] | BB16: =SUM(BB5:BB14)/SUM(BB32:BB41) -> 129.67164
B17: Technology | C17: biomass | D17: coal | E17: diesel | F17: geothermal | G17: hydro | H17: solar pv | I17: wind | J17: Frac of max solar | K17: Frac of max wind | P17: Technology | Q17: biomass | R17: coal | S17: diesel | T17: geothermal | U17: hydro | V17: solar pv | W17: wind | X17: Frac of max solar | Y17: Frac of max wind | AD17: Technology | AE17: biomass | AF17: coal | AG17: diesel | AH17: geothermal | AI17: hydro | AJ17: solar pv | AK17: wind | AL17: Frac of max solar | AM17: Frac of max wind | AR17: Technology | AS17: biomass | AT17: coal | AU17: diesel | AV17: geothermal | AW17: hydro | AX17: solar pv | AY17: wind | AZ17: Frac of max solar | BA17: Frac of max wind
B18: Country | P18: Country | AD18: Country | AR18: Country
B19: ATG | C19: NaN | D19: NaN | E19: 62.896125 | F19: NaN | G19: NaN | H19: 17.814974 | I19: 43.468814 | J19: =H19/('Max capacities'!$E4) -> 0.048148578 | K19: =I19/('Max capacities'!$F4) -> 0.43468814 | P19: ATG | Q19: NaN | R19: NaN | S19: 62.896125 | T19: NaN | U19: NaN | V19: 17.814974 | W19: 43.468814 | X19: =V19/('Max capacities'!$E4) -> 0.048148578 | Y19: =W19/('Max capacities'!$F4) -> 0.43468814 | AD19: ATG | AE19: NaN | AF19: NaN | AG19: 62.896125 | AH19: NaN | AI19: NaN | AJ19: 17.814974 | AK19: 43.468814 | AL19: =AJ19/('Max capacities'!$E4) -> 0.048148578 | AM19: =AK19/('Max capacities'!$F4) -> 0.43468814 | AR19: ATG | AS19: NaN | AT19: NaN | AU19: 62.97 | AV19: NaN | AW19: NaN | AX19: 44.530178 | AY19: 25 | AZ19: =AX19/('Max capacities'!$E4) -> 0.12035183 | BA19: =AY19/('Max capacities'!$F4) -> 0.25
B20: BRB | C20: 10 | D20: NaN | E20: 154.58444 | F20: NaN | G20: NaN | H20: 67 | I20: 113.38184 | J20: =H20/('Max capacities'!$E5) -> 0.11754386 | K20: =I20/('Max capacities'!$F5) -> 0.75587892 | P20: BRB | Q20: 10 | R20: NaN | S20: 156.35 | T20: NaN | U20: NaN | V20: 116.61952 | W20: 75 | X20: =V20/('Max capacities'!$E5) -> 0.20459565 | Y20: =W20/('Max capacities'!$F5) -> 0.5 | AD20: BRB | AE20: 10 | AF20: NaN | AG20: 154.58444 | AH20: NaN | AI20: NaN | AJ20: 67 | AK20: 113.38184 | AL20: =AJ20/('Max capacities'!$E5) -> 0.11754386 | AM20: =AK20/('Max capacities'!$F5) -> 0.75587892 | AR20: BRB | AS20: 10 | AT20: NaN | AU20: 162.32 | AV20: NaN | AW20: NaN | AX20: 142 | AY20: 38 | AZ20: =AX20/('Max capacities'!$E5) -> 0.24912281 | BA20: =AY20/('Max capacities'!$F5) -> 0.25333333
B21: DMA | C21: NaN | D21: NaN | E21: 0 | F21: 15 | G21: 6.6 | H21: 0 | I21: 0 | J21: =H21/('Max capacities'!$E6) -> 0 | K21: =I21/('Max capacities'!$F6) -> 0 | P21: DMA | Q21: NaN | R21: NaN | S21: 0 | T21: 15 | U21: 6.6 | V21: 0 | W21: 0 | X21: =V21/('Max capacities'!$E6) -> 0 | Y21: =W21/('Max capacities'!$F6) -> 0 | AD21: DMA | AE21: NaN | AF21: NaN | AG21: 0 | AH21: 15 | AI21: 6.6 | AJ21: 0 | AK21: 0 | AL21: =AJ21/('Max capacities'!$E6) -> 0 | AM21: =AK21/('Max capacities'!$F6) -> 0 | AR21: DMA | AS21: NaN | AT21: NaN | AU21: 0 | AV21: 15 | AW21: 6.6 | AX21: 0 | AY21: 0 | AZ21: =AX21/('Max capacities'!$E6) -> 0 | BA21: =AY21/('Max capacities'!$F6) -> 0
B22: GLP | C22: 10 | D22: 0 | E22: 214.4999 | F22: 50 | G22: 15 | H22: 82.014955 | I22: 158.34192 | J22: =H22/('Max capacities'!$E7) -> 0.037279525 | K22: =I22/('Max capacities'!$F7) -> 0.26390319 | P22: GLP | Q22: 10 | R22: 0 | S22: 214.4999 | T22: 50 | U22: 15 | V22: 82.014955 | W22: 158.34192 | X22: =V22/('Max capacities'!$E7) -> 0.037279525 | Y22: =W22/('Max capacities'!$F7) -> 0.26390319 | AD22: GLP | AE22: 10 | AF22: 0 | AG22: 214.4999 | AH22: 50 | AI22: 15 | AJ22: 82.014955 | AK22: 158.34192 | AL22: =AJ22/('Max capacities'!$E7) -> 0.037279525 | AM22: =AK22/('Max capacities'!$F7) -> 0.26390319 | AR22: GLP | AS22: 10 | AT22: 0 | AU22: 214.6 | AV22: 50 | AW22: 15 | AX22: 95.652174 | AY22: 150 | AZ22: =AX22/('Max capacities'!$E7) -> 0.043478261 | BA22: =AY22/('Max capacities'!$F7) -> 0.25
B23: GRD | C23: NaN | D23: NaN | E23: 21.092327 | F23: 18.319054 | G23: 0 | H23: 9.951496 | I23: 12.659537 | J23: =H23/('Max capacities'!$E8) -> 0.021173396 | K23: =I23/('Max capacities'!$F8) -> 0.10549614 | P23: GRD | Q23: NaN | R23: NaN | S23: 21.092327 | T23: 18.319054 | U23: 0 | V23: 9.951496 | W23: 12.659537 | X23: =V23/('Max capacities'!$E8) -> 0.021173396 | Y23: =W23/('Max capacities'!$F8) -> 0.10549614 | AD23: GRD | AE23: NaN | AF23: NaN | AG23: 19.860388 | AH23: 20 | AI23: 0 | AJ23: 9.738624 | AK23: 11.302476 | AL23: =AJ23/('Max capacities'!$E8) -> 0.020720477 | AM23: =AK23/('Max capacities'!$F8) -> 0.0941873 | AR23: GRD | AS23: NaN | AT23: NaN | AU23: 21.092327 | AV23: 18.319054 | AW23: 0 | AX23: 9.951496 | AY23: 12.659537 | AZ23: =AX23/('Max capacities'!$E8) -> 0.021173396 | BA23: =AY23/('Max capacities'!$F8) -> 0.10549614
B24: LCA | C24: NaN | D24: NaN | E24: 41.370048 | F24: 30 | G24: NaN | H24: 16.999887 | I24: 25.026767 | J24: =H24/('Max capacities'!$E9) -> 0.021249859 | K24: =I24/('Max capacities'!$F9) -> 0.12513383 | P24: LCA | Q24: NaN | R24: NaN | S24: 41.370048 | T24: 30 | U24: NaN | V24: 16.999887 | W24: 25.026767 | X24: =V24/('Max capacities'!$E9) -> 0.021249859 | Y24: =W24/('Max capacities'!$F9) -> 0.12513383 | AD24: LCA | AE24: NaN | AF24: NaN | AG24: 41.370048 | AH24: 30 | AI24: NaN | AJ24: 16.999887 | AK24: 25.026767 | AL24: =AJ24/('Max capacities'!$E9) -> 0.021249859 | AM24: =AK24/('Max capacities'!$F9) -> 0.12513383 | AR24: LCA | AS24: NaN | AT24: NaN | AU24: 41.370048 | AV24: 30 | AW24: NaN | AX24: 16.999887 | AY24: 25.026767 | AZ24: =AX24/('Max capacities'!$E9) -> 0.021249859 | BA24: =AY24/('Max capacities'!$F9) -> 0.12513383
B25: MSR | C25: NaN | D25: NaN | E25: 1.09128 | F25: 1.5 | G25: NaN | H25: 1 | I25: 0.159483 | J25: =H25/('Max capacities'!$E10) -> 0.007518797 | K25: =I25/('Max capacities'!$F10) -> 0.0053161 | P25: MSR | Q25: NaN | R25: NaN | S25: 1.09128 | T25: 1.5 | U25: NaN | V25: 1 | W25: 0.159483 | X25: =V25/('Max capacities'!$E10) -> 0.007518797 | Y25: =W25/('Max capacities'!$F10) -> 0.0053161 | AD25: MSR | AE25: NaN | AF25: NaN | AG25: 1.075469 | AH25: 1.539554 | AI25: NaN | AJ25: 1 | AK25: 0.127515 | AL25: =AJ25/('Max capacities'!$E10) -> 0.007518797 | AM25: =AK25/('Max capacities'!$F10) -> 0.0042505 | AR25: MSR | AS25: NaN | AT25: NaN | AU25: 1.09128 | AV25: 1.5 | AW25: NaN | AX25: 1 | AY25: 0.159483 | AZ25: =AX25/('Max capacities'!$E10) -> 0.007518797 | BA25: =AY25/('Max capacities'!$F10) -> 0.0053161
B26: MTQ | C26: 41.4 | D26: NaN | E26: 167.81872 | F26: 50 | G26: NaN | H26: 76.7 | I26: 135.25136 | J26: =H26/('Max capacities'!$E11) -> 0.051133333 | K26: =I26/('Max capacities'!$F11) -> 0.33812839 | P26: MTQ | Q26: 41.4 | R26: NaN | S26: 167.81872 | T26: 50 | U26: NaN | V26: 76.7 | W26: 135.25136 | X26: =V26/('Max capacities'!$E11) -> 0.051133333 | Y26: =W26/('Max capacities'!$F11) -> 0.33812839 | AD26: MTQ | AE26: 41.4 | AF26: NaN | AG26: 167.81872 | AH26: 50 | AI26: NaN | AJ26: 76.7 | AK26: 135.25136 | AL26: =AJ26/('Max capacities'!$E11) -> 0.051133333 | AM26: =AK26/('Max capacities'!$F11) -> 0.33812839 | AR26: MTQ | AS26: 41.4 | AT26: NaN | AU26: 168.7 | AV26: 50 | AW26: NaN | AX26: 135.32986 | AY26: 100 | AZ26: =AX26/('Max capacities'!$E11) -> 0.090219907 | BA26: =AY26/('Max capacities'!$F11) -> 0.25
B27: SKN | C27: NaN | D27: NaN | E27: 14.878027 | F27: 27.002192 | G27: NaN | H27: 8.675649 | I27: 6.5685 | J27: =H27/('Max capacities'!$E12) -> 0.024787569 | K27: =I27/('Max capacities'!$F12) -> 0.065685 | P27: SKN | Q27: NaN | R27: NaN | S27: 14.878027 | T27: 27.002192 | U27: NaN | V27: 8.675649 | W27: 6.5685 | X27: =V27/('Max capacities'!$E12) -> 0.024787569 | Y27: =W27/('Max capacities'!$F12) -> 0.065685 | AD27: SKN | AE27: NaN | AF27: NaN | AG27: 12.18 | AH27: 30 | AI27: NaN | AJ27: 8.466227 | AK27: 4.264857 | AL27: =AJ27/('Max capacities'!$E12) -> 0.02418922 | AM27: =AK27/('Max capacities'!$F12) -> 0.04264857 | AR27: SKN | AS27: NaN | AT27: NaN | AU27: 14.878027 | AV27: 27.002192 | AW27: NaN | AX27: 8.675649 | AY27: 6.5685 | AZ27: =AX27/('Max capacities'!$E12) -> 0.024787569 | BA27: =AY27/('Max capacities'!$F12) -> 0.065685
B28: SVG | C28: NaN | D28: NaN | E28: 17.024109 | F28: 0 | G28: 8 | H28: 7.015679 | I28: 18.903088 | J28: =H28/('Max capacities'!$E13) -> 0.015251476 | K28: =I28/('Max capacities'!$F13) -> 0.15752573 | P28: SVG | Q28: NaN | R28: NaN | S28: 17.024109 | T28: 0 | U28: 8 | V28: 7.015679 | W28: 18.903088 | X28: =V28/('Max capacities'!$E13) -> 0.015251476 | Y28: =W28/('Max capacities'!$F13) -> 0.15752573 | AD28: SVG | AE28: NaN | AF28: NaN | AG28: 17.024109 | AH28: 0 | AI28: 8 | AJ28: 7.015679 | AK28: 18.903088 | AL28: =AJ28/('Max capacities'!$E13) -> 0.015251476 | AM28: =AK28/('Max capacities'!$F13) -> 0.15752573 | AR28: SVG | AS28: NaN | AT28: NaN | AU28: 17.024109 | AV28: 0 | AW28: 8 | AX28: 7.015679 | AY28: 18.903088 | AZ28: =AX28/('Max capacities'!$E13) -> 0.015251476 | BA28: =AY28/('Max capacities'!$F13) -> 0.15752573
B29: Generation [GWh] | J29: solar pv fraction | K29: wind fraction | L29: total generation | M29: CO2 emissions [ktCO2] | N29: Cost of CO2 reduction [$/tCO2] | P29: Generation [GWh] | X29: solar pv fraction | Y29: wind fraction | Z29: total generation | AA29: CO2 emissions [ktCO2] | AB29: Cost of CO2 reduction [$/tCO2] | AD29: Generation [GWh] | AL29: solar pv fraction | AM29: wind fraction | AN29: total generation | AO29: CO2 emissions [ktCO2] | AP29: Cost of CO2 reduction [$/tCO2] | AR29: Generation [GWh] | AZ29: solar pv fraction | BA29: wind fraction | BB29: total generation | BC29: CO2 emissions [ktCO2] | BD29: Cost of CO2 reduction [$/tCO2]
B30: Technology | C30: biomass | D30: coal | E30: diesel | F30: geothermal | G30: hydro | H30: solar pv | I30: wind | P30: Technology | Q30: biomass | R30: coal | S30: diesel | T30: geothermal | U30: hydro | V30: solar pv | W30: wind | AD30: Technology | AE30: biomass | AF30: coal | AG30: diesel | AH30: geothermal | AI30: hydro | AJ30: solar pv | AK30: wind | AR30: Technology | AS30: biomass | AT30: coal | AU30: diesel | AV30: geothermal | AW30: hydro | AX30: solar pv | AY30: wind
B31: Country | P31: Country | AD31: Country | AR31: Country
B32: ATG | C32: NaN | D32: NaN | E32: 211.91851 | F32: NaN | G32: NaN | H32: 31.586643 | I32: 193.51089 | J32: =H32/(SUM(C32:I32)) -> 0.072277995 | K32: =I32/(SUM(C32:I32)) -> 0.44280043 | L32: =SUM(C32:I32) -> 437.01604 | M32: =E32*$E$57 -> 139.86621 | N32: =-(G5-'0. Current system'!$G5)*SUM(C32:I32)/(M32-'0. Current system'!$L32) -> -200.13026 | P32: ATG | Q32: NaN | R32: NaN | S32: 211.91851 | T32: NaN | U32: NaN | V32: 31.586643 | W32: 193.51089 | X32: =V32/(SUM(Q32:W32)) -> 0.072277995 | Y32: =W32/(SUM(Q32:W32)) -> 0.44280043 | Z32: =SUM(Q32:W32) -> 437.01604 | AA32: =S32*$E$57 -> 139.86621 | AB32: =-(U5-'0. Current system'!$G5)*SUM(Q32:W32)/(AA32-'0. Current system'!$L32) -> -200.13026 | AD32: ATG | AE32: NaN | AF32: NaN | AG32: 211.91851 | AH32: NaN | AI32: NaN | AJ32: 31.586643 | AK32: 193.51089 | AL32: =AJ32/(SUM(AE32:AK32)) -> 0.072277995 | AM32: =AK32/(SUM(AE32:AK32)) -> 0.44280043 | AN32: =SUM(AE32:AK32) -> 437.01604 | AO32: =AG32*$E$57 -> 139.86621 | AP32: =-(AI5-'0. Current system'!$G5)*SUM(AE32:AK32)/(AO32-'0. Current system'!$L32) -> -95.298068 | AR32: ATG | AS32: NaN | AT32: NaN | AU32: 246.53861 | AV32: NaN | AW32: NaN | AX32: 78.917462 | AY32: 111.55996 | AZ32: =AX32/(SUM(AS32:AY32)) -> 0.18058253 | BA32: =AY32/(SUM(AS32:AY32)) -> 0.25527659 | BB32: =SUM(AS32:AY32) -> 437.01604 | BC32: =AU32*$E$57 -> 162.71549 | BD32: =-(AW5-'0. Current system'!$G5)*SUM(AS32:AY32)/(BC32-'0. Current system'!$L32) -> -176.24063
B33: BRB | C33: 84.42099 | D33: NaN | E33: 438.71941 | F33: NaN | G33: NaN | H33: 118.20689 | I33: 560.57482 | J33: =H33/(SUM(C33:I33)) -> 0.098348209 | K33: =I33/(SUM(C33:I33)) -> 0.46639863 | L33: =SUM(C33:I33) -> 1201.9221 | M33: =E33*$E$57 -> 289.55481 | N33: =-(G6-'0. Current system'!$G6)*SUM(C33:I33)/(M33-'0. Current system'!$L33) -> -193.40914 | P33: BRB | Q33: 85.130658 | R33: NaN | S33: 540.50327 | T33: NaN | U33: NaN | V33: 205.54118 | W33: 370.747 | X33: =V33/(SUM(Q33:W33)) -> 0.1710104 | Y33: =W33/(SUM(Q33:W33)) -> 0.30846175 | Z33: =SUM(Q33:W33) -> 1201.9221 | AA33: =S33*$E$57 -> 356.73216 | AB33: =-(U6-'0. Current system'!$G6)*SUM(Q33:W33)/(AA33-'0. Current system'!$L33) -> -166.57909 | AD33: BRB | AE33: 84.42099 | AF33: NaN | AG33: 438.71941 | AH33: NaN | AI33: NaN | AJ33: 118.208 | AK33: 560.57371 | AL33: =AJ33/(SUM(AE33:AK33)) -> 0.098349133 | AM33: =AK33/(SUM(AE33:AK33)) -> 0.4663977 | AN33: =SUM(AE33:AK33) -> 1201.9221 | AO33: =AG33*$E$57 -> 289.55481 | AP33: =-(AI6-'0. Current system'!$G6)*SUM(AE33:AK33)/(AO33-'0. Current system'!$L33) -> -112.12664 | AR33: BRB | AS33: 86.458586 | AT33: NaN | AU33: 676.58671 | AV33: NaN | AW33: NaN | AX33: 250.66751 | AY33: 188.20929 | AZ33: =AX33/(SUM(AS33:AY33)) -> 0.20855554 | BA33: =AY33/(SUM(AS33:AY33)) -> 0.15659025 | BB33: =SUM(AS33:AY33) -> 1201.9221 | BC33: =AU33*$E$57 -> 446.54723 | BD33: =-(AW6-'0. Current system'!$G6)*SUM(AS33:AY33)/(BC33-'0. Current system'!$L33) -> -110.42003
B34: DMA | C34: NaN | D34: NaN | E34: 0 | F34: 82.7372 | G34: 44.7437 | H34: 0 | I34: 0 | J34: =H34/(SUM(C34:I34)) -> 0 | K34: =I34/(SUM(C34:I34)) -> 0 | L34: =SUM(C34:I34) -> 127.4809 | M34: =E34*$E$57 -> 0 | N34: =-(G7-'0. Current system'!$G7)*SUM(C34:I34)/(M34-'0. Current system'!$L34) -> -47.932955 | P34: DMA | Q34: NaN | R34: NaN | S34: 0 | T34: 82.7372 | U34: 44.7437 | V34: 0 | W34: 0 | X34: =V34/(SUM(Q34:W34)) -> 0 | Y34: =W34/(SUM(Q34:W34)) -> 0 | Z34: =SUM(Q34:W34) -> 127.4809 | AA34: =S34*$E$57 -> 0 | AB34: =-(U7-'0. Current system'!$G7)*SUM(Q34:W34)/(AA34-'0. Current system'!$L34) -> -47.932955 | AD34: DMA | AE34: NaN | AF34: NaN | AG34: 0 | AH34: 82.7372 | AI34: 44.7437 | AJ34: 0 | AK34: 0 | AL34: =AJ34/(SUM(AE34:AK34)) -> 0 | AM34: =AK34/(SUM(AE34:AK34)) -> 0 | AN34: =SUM(AE34:AK34) -> 127.4809 | AO34: =AG34*$E$57 -> 0 | AP34: =-(AI7-'0. Current system'!$G7)*SUM(AE34:AK34)/(AO34-'0. Current system'!$L34) -> -47.932955 | AR34: DMA | AS34: NaN | AT34: NaN | AU34: 0 | AV34: 82.7372 | AW34: 44.7437 | AX34: 0 | AY34: 0 | AZ34: =AX34/(SUM(AS34:AY34)) -> 0 | BA34: =AY34/(SUM(AS34:AY34)) -> 0 | BB34: =SUM(AS34:AY34) -> 127.4809 | BC34: =AU34*$E$57 -> 0 | BD34: =-(AW7-'0. Current system'!$G7)*SUM(AS34:AY34)/(BC34-'0. Current system'!$L34) -> -47.932955
B35: GLP | C35: 78.661453 | D35: 0 | E35: 542.30147 | F35: 386.64283 | G35: 127.69013 | H35: 145.39126 | I35: 722.48306 | J35: =H35/(SUM(C35:I35)) -> 0.072580583 | K35: =I35/(SUM(C35:I35)) -> 0.36066983 | L35: =SUM(C35:I35) -> 2003.1702 | M35: =E35*$E$57 -> 357.91897 | N35: =-(G8-'0. Current system'!$G8)*SUM(C35:I35)/(M35-'0. Current system'!$L35) -> -169.82858 | P35: GLP | Q35: 78.661453 | R35: 0 | S35: 542.30147 | T35: 386.64283 | U35: 127.69013 | V35: 145.38849 | W35: 722.48582 | X35: =V35/(SUM(Q35:W35)) -> 0.072579201 | Y35: =W35/(SUM(Q35:W35)) -> 0.36067121 | Z35: =SUM(Q35:W35) -> 2003.1702 | AA35: =S35*$E$57 -> 357.91897 | AB35: =-(U8-'0. Current system'!$G8)*SUM(Q35:W35)/(AA35-'0. Current system'!$L35) -> -169.82858 | AD35: GLP | AE35: 78.661453 | AF35: 0 | AG35: 542.30147 | AH35: 386.64283 | AI35: 127.69013 | AJ35: 145.39126 | AK35: 722.48306 | AL35: =AJ35/(SUM(AE35:AK35)) -> 0.072580583 | AM35: =AK35/(SUM(AE35:AK35)) -> 0.36066983 | AN35: =SUM(AE35:AK35) -> 2003.1702 | AO35: =AG35*$E$57 -> 357.91897 | AP35: =-(AI8-'0. Current system'!$G8)*SUM(AE35:AK35)/(AO35-'0. Current system'!$L35) -> -111.26384 | AR35: GLP | AS35: 79.807239 | AT35: 0 | AU35: 553.08234 | AV35: 387.6632 | AW35: 128.14704 | AX35: 169.60338 | AY35: 684.86701 | AZ35: =AX35/(SUM(AS35:AY35)) -> 0.084667482 | BA35: =AY35/(SUM(AS35:AY35)) -> 0.34189157 | BB35: =SUM(AS35:AY35) -> 2003.1702 | BC35: =AU35*$E$57 -> 365.03434 | BD35: =-(AW8-'0. Current system'!$G8)*SUM(AS35:AY35)/(BC35-'0. Current system'!$L35) -> -167.51099
B36: GRD | C36: NaN | D36: NaN | E36: 45.268473 | F36: 140.52001 | G36: 0 | H36: 17.093386 | I36: 61.136835 | J36: =H36/(SUM(C36:I36)) -> 0.064743088 | K36: =I36/(SUM(C36:I36)) -> 0.23156252 | L36: =SUM(C36:I36) -> 264.0187 | M36: =E36*$E$57 -> 29.877192 | N36: =-(G9-'0. Current system'!$G9)*SUM(C36:I36)/(M36-'0. Current system'!$L36) -> -155.74888 | P36: GRD | Q36: NaN | R36: NaN | S36: 45.268473 | T36: 140.52001 | U36: 0 | V36: 17.095086 | W36: 61.135135 | X36: =V36/(SUM(Q36:W36)) -> 0.064749527 | Y36: =W36/(SUM(Q36:W36)) -> 0.23155608 | Z36: =SUM(Q36:W36) -> 264.0187 | AA36: =S36*$E$57 -> 29.877192 | AB36: =-(U9-'0. Current system'!$G9)*SUM(Q36:W36)/(AA36-'0. Current system'!$L36) -> -155.74888 | AD36: GRD | AE36: NaN | AF36: NaN | AG36: 39.783247 | AH36: 152.90993 | AI36: 0 | AJ36: 16.729766 | AK36: 54.595752 | AL36: =AJ36/(SUM(AE36:AK36)) -> 0.063365837 | AM36: =AK36/(SUM(AE36:AK36)) -> 0.20678744 | AN36: =SUM(AE36:AK36) -> 264.0187 | AO36: =AG36*$E$57 -> 26.256943 | AP36: =-(AI9-'0. Current system'!$G9)*SUM(AE36:AK36)/(AO36-'0. Current system'!$L36) -> -132.29705 | AR36: GRD | AS36: NaN | AT36: NaN | AU36: 45.268473 | AV36: 140.52001 | AW36: 0 | AX36: 17.093372 | AY36: 61.13685 | AZ36: =AX36/(SUM(AS36:AY36)) -> 0.064743035 | BA36: =AY36/(SUM(AS36:AY36)) -> 0.23156257 | BB36: =SUM(AS36:AY36) -> 264.0187 | BC36: =AU36*$E$57 -> 29.877192 | BD36: =-(AW9-'0. Current system'!$G9)*SUM(AS36:AY36)/(BC36-'0. Current system'!$L36) -> -155.74888
B37: LCA | C37: NaN | D37: NaN | E37: 88.268638 | F37: 230.60054 | G37: NaN | H37: 30.029614 | I37: 124.54061 | J37: =H37/(SUM(C37:I37)) -> 0.063428633 | K37: =I37/(SUM(C37:I37)) -> 0.26305502 | L37: =SUM(C37:I37) -> 473.4394 | M37: =E37*$E$57 -> 58.257301 | N37: =-(G10-'0. Current system'!$G10)*SUM(C37:I37)/(M37-'0. Current system'!$L37) -> -160.27901 | P37: LCA | Q37: NaN | R37: NaN | S37: 88.268638 | T37: 230.60054 | U37: NaN | V37: 30.030317 | W37: 124.53991 | X37: =V37/(SUM(Q37:W37)) -> 0.063430118 | Y37: =W37/(SUM(Q37:W37)) -> 0.26305353 | Z37: =SUM(Q37:W37) -> 473.4394 | AA37: =S37*$E$57 -> 58.257301 | AB37: =-(U10-'0. Current system'!$G10)*SUM(Q37:W37)/(AA37-'0. Current system'!$L37) -> -160.27901 | AD37: LCA | AE37: NaN | AF37: NaN | AG37: 88.268638 | AH37: 230.60054 | AI37: NaN | AJ37: 30.029944 | AK37: 124.54028 | AL37: =AJ37/(SUM(AE37:AK37)) -> 0.06342933 | AM37: =AK37/(SUM(AE37:AK37)) -> 0.26305432 | AN37: =SUM(AE37:AK37) -> 473.4394 | AO37: =AG37*$E$57 -> 58.257301 | AP37: =-(AI10-'0. Current system'!$G10)*SUM(AE37:AK37)/(AO37-'0. Current system'!$L37) -> -135.04528 | AR37: LCA | AS37: NaN | AT37: NaN | AU37: 88.268638 | AV37: 230.60054 | AW37: NaN | AX37: 30.02049 | AY37: 124.54973 | AZ37: =AX37/(SUM(AS37:AY37)) -> 0.063409361 | BA37: =AY37/(SUM(AS37:AY37)) -> 0.26307429 | BB37: =SUM(AS37:AY37) -> 473.4394 | BC37: =AU37*$E$57 -> 58.257301 | BD37: =-(AW10-'0. Current system'!$G10)*SUM(AS37:AY37)/(BC37-'0. Current system'!$L37) -> -160.27901
B38: MSR | C38: NaN | D38: NaN | E38: 2.348794 | F38: 11.556343 | G38: NaN | H38: 1.775371 | I38: 0.710011 | J38: =H38/(SUM(C38:I38)) -> 0.10831695 | K38: =I38/(SUM(C38:I38)) -> 0.043318396 | L38: =SUM(C38:I38) -> 16.390519 | M38: =E38*$E$57 -> 1.550204 | N38: =-(G11-'0. Current system'!$G11)*SUM(C38:I38)/(M38-'0. Current system'!$L38) -> -125.51474 | P38: MSR | Q38: NaN | R38: NaN | S38: 2.348794 | T38: 11.556343 | U38: NaN | V38: 1.775361 | W38: 0.710022 | X38: =V38/(SUM(Q38:W38)) -> 0.10831633 | Y38: =W38/(SUM(Q38:W38)) -> 0.043319065 | Z38: =SUM(Q38:W38) -> 16.39052 | AA38: =S38*$E$57 -> 1.550204 | AB38: =-(U11-'0. Current system'!$G11)*SUM(Q38:W38)/(AA38-'0. Current system'!$L38) -> -125.51474 | AD38: MSR | AE38: NaN | AF38: NaN | AG38: 2.208068 | AH38: 11.839939 | AI38: NaN | AJ38: 1.774854 | AK38: 0.56766 | AL38: =AJ38/(SUM(AE38:AK38)) -> 0.10828539 | AM38: =AK38/(SUM(AE38:AK38)) -> 0.034633432 | AN38: =SUM(AE38:AK38) -> 16.390521 | AO38: =AG38*$E$57 -> 1.4573249 | AP38: =-(AI11-'0. Current system'!$G11)*SUM(AE38:AK38)/(AO38-'0. Current system'!$L38) -> -105.10363 | AR38: MSR | AS38: NaN | AT38: NaN | AU38: 2.348794 | AV38: 11.556343 | AW38: NaN | AX38: 1.775358 | AY38: 0.710024 | AZ38: =AX38/(SUM(AS38:AY38)) -> 0.10831616 | BA38: =AY38/(SUM(AS38:AY38)) -> 0.04331919 | BB38: =SUM(AS38:AY38) -> 16.390519 | BC38: =AU38*$E$57 -> 1.550204 | BD38: =-(AW11-'0. Current system'!$G11)*SUM(AS38:AY38)/(BC38-'0. Current system'!$L38) -> -125.51474
B39: MTQ | C39: 315.85131 | D39: NaN | E39: 309.11482 | F39: 390.82113 | G39: NaN | H39: 136.11284 | I39: 669.1732 | J39: =H39/(SUM(C39:I39)) -> 0.074743197 | K39: =I39/(SUM(C39:I39)) -> 0.36746088 | L39: =SUM(C39:I39) -> 1821.0733 | M39: =E39*$E$57 -> 204.01578 | N39: =-(G12-'0. Current system'!$G12)*SUM(C39:I39)/(M39-'0. Current system'!$L39) -> -194.78905 | P39: MTQ | Q39: 315.85131 | R39: NaN | S39: 309.11482 | T39: 390.82113 | U39: NaN | V39: 136.07818 | W39: 669.20786 | X39: =V39/(SUM(Q39:W39)) -> 0.074724162 | Y39: =W39/(SUM(Q39:W39)) -> 0.36747991 | Z39: =SUM(Q39:W39) -> 1821.0733 | AA39: =S39*$E$57 -> 204.01578 | AB39: =-(U12-'0. Current system'!$G12)*SUM(Q39:W39)/(AA39-'0. Current system'!$L39) -> -194.78905 | AD39: MTQ | AE39: 315.85131 | AF39: NaN | AG39: 309.11482 | AH39: 390.82113 | AI39: NaN | AJ39: 136.11789 | AK39: 669.16815 | AL39: =AJ39/(SUM(AE39:AK39)) -> 0.074745969 | AM39: =AK39/(SUM(AE39:AK39)) -> 0.36745811 | AN39: =SUM(AE39:AK39) -> 1821.0733 | AO39: =AG39*$E$57 -> 204.01578 | AP39: =-(AI12-'0. Current system'!$G12)*SUM(AE39:AK39)/(AO39-'0. Current system'!$L39) -> -160.21949 | AR39: MTQ | AS39: 330.9495 | AT39: NaN | AU39: 363.6755 | AV39: 391.59759 | AW39: NaN | AX39: 239.98416 | AY39: 494.86656 | AZ39: =AX39/(SUM(AS39:AY39)) -> 0.13178171 | BA39: =AY39/(SUM(AS39:AY39)) -> 0.27174445 | BB39: =SUM(AS39:AY39) -> 1821.0733 | BC39: =AU39*$E$57 -> 240.02583 | BD39: =-(AW12-'0. Current system'!$G12)*SUM(AS39:AY39)/(BC39-'0. Current system'!$L39) -> -181.76128
B40: SKN | C40: NaN | D40: NaN | E40: 25.726569 | F40: 203.63075 | G40: NaN | H40: 15.364318 | I40: 28.461207 | J40: =H40/(SUM(C40:I40)) -> 0.056241884 | K40: =I40/(SUM(C40:I40)) -> 0.10418373 | L40: =SUM(C40:I40) -> 273.18285 | M40: =E40*$E$57 -> 16.979536 | N40: =-(G13-'0. Current system'!$G13)*SUM(C40:I40)/(M40-'0. Current system'!$L40) -> -133.18132 | P40: SKN | Q40: NaN | R40: NaN | S40: 25.726569 | T40: 203.63075 | U40: NaN | V40: 15.363413 | W40: 28.462113 | X40: =V40/(SUM(Q40:W40)) -> 0.056238571 | Y40: =W40/(SUM(Q40:W40)) -> 0.10418704 | Z40: =SUM(Q40:W40) -> 273.18285 | AA40: =S40*$E$57 -> 16.979536 | AB40: =-(U13-'0. Current system'!$G13)*SUM(Q40:W40)/(AA40-'0. Current system'!$L40) -> -133.18132 | AD40: SKN | AE40: NaN | AF40: NaN | AG40: 17.240653 | AH40: 222.46514 | AI40: NaN | AJ40: 14.993953 | AK40: 18.483101 | AL40: =AJ40/(SUM(AE40:AK40)) -> 0.054886143 | AM40: =AK40/(SUM(AE40:AK40)) -> 0.06765835 | AN40: =SUM(AE40:AK40) -> 273.18285 | AO40: =AG40*$E$57 -> 11.378831 | AP40: =-(AI13-'0. Current system'!$G13)*SUM(AE40:AK40)/(AO40-'0. Current system'!$L40) -> -120.13988 | AR40: SKN | AS40: NaN | AT40: NaN | AU40: 25.726569 | AV40: 203.63075 | AW40: NaN | AX40: 15.361233 | AY40: 28.464292 | AZ40: =AX40/(SUM(AS40:AY40)) -> 0.056230591 | BA40: =AY40/(SUM(AS40:AY40)) -> 0.10419502 | BB40: =SUM(AS40:AY40) -> 273.18285 | BC40: =AU40*$E$57 -> 16.979536 | BD40: =-(AW13-'0. Current system'!$G13)*SUM(AS40:AY40)/(BC40-'0. Current system'!$L40) -> -133.18132
B41: SVG | C41: NaN | D41: NaN | E41: 23.199607 | F41: 0 | G41: 56.161992 | H41: 12.324951 | I41: 90.43005 | J41: =H41/(SUM(C41:I41)) -> 0.067676154 | K41: =I41/(SUM(C41:I41)) -> 0.49655029 | L41: =SUM(C41:I41) -> 182.1166 | M41: =E41*$E$57 -> 15.311741 | N41: =-(G14-'0. Current system'!$G14)*SUM(C41:I41)/(M41-'0. Current system'!$L41) -> -236.12181 | P41: SVG | Q41: NaN | R41: NaN | S41: 23.199607 | T41: 0 | U41: 56.161992 | V41: 12.329741 | W41: 90.42526 | X41: =V41/(SUM(Q41:W41)) -> 0.067702455 | Y41: =W41/(SUM(Q41:W41)) -> 0.49652399 | Z41: =SUM(Q41:W41) -> 182.1166 | AA41: =S41*$E$57 -> 15.311741 | AB41: =-(U14-'0. Current system'!$G14)*SUM(Q41:W41)/(AA41-'0. Current system'!$L41) -> -236.12181 | AD41: SVG | AE41: NaN | AF41: NaN | AG41: 23.199607 | AH41: 0 | AI41: 56.161992 | AJ41: 12.324951 | AK41: 90.43005 | AL41: =AJ41/(SUM(AE41:AK41)) -> 0.067676154 | AM41: =AK41/(SUM(AE41:AK41)) -> 0.49655029 | AN41: =SUM(AE41:AK41) -> 182.1166 | AO41: =AG41*$E$57 -> 15.311741 | AP41: =-(AI14-'0. Current system'!$G14)*SUM(AE41:AK41)/(AO41-'0. Current system'!$L41) -> -236.12181 | AR41: SVG | AS41: NaN | AT41: NaN | AU41: 23.199607 | AV41: 0 | AW41: 56.161992 | AX41: 12.334706 | AY41: 90.420294 | AZ41: =AX41/(SUM(AS41:AY41)) -> 0.067729719 | BA41: =AY41/(SUM(AS41:AY41)) -> 0.49649672 | BB41: =SUM(AS41:AY41) -> 182.1166 | BC41: =AU41*$E$57 -> 15.311741 | BD41: =-(AW14-'0. Current system'!$G14)*SUM(AS41:AY41)/(BC41-'0. Current system'!$L41) -> -236.12181
...

Sheet 1. LCOE summaries
E1: Diesel, RE, no storage
F2: Regional LCOE | H2: % difference to base
D3: 1.1 | E3: Base | F3: ='1. Diesel, no storage'!G3 -> 118.9 | G3: /MWh | H3: --
D4: 1.2 | E4: Half wind and solar max cap | F4: ='1. Diesel, no storage'!U3 -> 122 | G4: /MWh | H4: =(F4-F$3)/F$3 -> 0.02607233
D5: 1.3 | E5: Higher fuel cost | F5: ='1. Diesel, no storage'!AI3 -> 135.9 | G5: /MWh | H5: =(F5-F$3)/F$3 -> 0.14297729
D6: 1.4 | E6: Quarter wind and solar max cap | F6: ='1. Diesel, no storage'!AW3 -> 130 | G6: /MWh | H6: =(F6-F$3)/F$3 -> 0.093355761

Sheet 2. Diesel-battery-storage
B1: Storage, 4 hours,double max wind and solar capacity | G1: Storage_4-hr_newbaseline-wind-solar-geo | T1: Baseline costs | W1: Storage_4-hr_half-wind-solar | AL1: Storage, 4 hours,new base max wind and solar capacity, high storage cost | AS1: Storage_4-hr_high-batt-cost | AZ1: Baseline costs | BC1: Storage_6-hr_baseline-VRE | BR1: Baseline costs | BU1: Storage_2-hr_half-wind-solar-cap | CJ1: Baseline costs | CM1: Storage_6-hr_half-wind-solar-cap | CX1: Baseline costs | DA1: Storage_8-hr_half-wind-solar-cap
B2: 04.09.2025 | D2: 2.1 | F2: lcoe | G2: $/MWh | H2: compared to current system | I2: compared to no storage | T2: 04.09.2025 | V2: half wind and solar max cap | X2: lcoe | Y2: $/MWh | AL2: 04.09.2025 | AN2: 2.3 | AP2: lcoe | AQ2: $/MWh | AZ2: 04.09.2025 | BA2: 2.4 | BB2: Now baseline wind and solar, longer storage time | BR2: 04.09.2025 | BU2: half wind and solar, shorter storage time | CJ2: 05.09.2025 | CL2: This is now "half wind and solar + 6hr storage | CX2: 05.09.2025 | CY2: 2.7 | DA2: half wind and solar, 8-hr storage
B3: 4 | C3: hours | D3: this becomes the baseline | F3: Region | G3: 92.2 | H3: =(G3-'0. Current system'!$G3)/'0. Current system'!$G3 -> -0.49617486 | I3: =(G3-'1. Diesel, no storage'!$G3)/'1. Diesel, no storage'!$G3 -> -0.22455845 | L3: Also must run wind, solar, geo min 60% | T3: 4 | U3: hours | V3: 2.2 | X3: Region | Y3: 93.8 | Z3: =(Y3-'0. Current system'!$G3)/'0. Current system'!$G3 -> -0.48743169 | AA3: =(Y3-'1. Diesel, no storage'!$G3)/'1. Diesel, no storage'!$G3 -> -0.21110177 | AB3: =(Y3-$G3)/$G3 -> 0.017353579 | AD3: Also must run wind, solar, geo min 60% | AL3: 4 | AM3: hours | AP3: Region | AQ3: 95.3 | AR3: =(AQ3-'0. Current system'!$G3)/'0. Current system'!$G3 -> -0.47923497 | AS3: =(AQ3-'1. Diesel, no storage'!$G3)/'1. Diesel, no storage'!$G3 -> -0.19848612 | AT3: =(AQ3-$G3)/$G3 -> 0.03362256 | AV3: Also must run wind, solar, geo min 60% | AZ3: 6 | BA3: hours | BD3: lcoe | BE3: 90.1 | BF3: =(BE3-'0. Current system'!$G3)/'0. Current system'!$G3 -> -0.50765027 | BG3: =(BE3-'1. Diesel, no storage'!$G3)/'1. Diesel, no storage'!$G3 -> -0.24222035 | BH3: =(BE3-$G3)/$G3 -> -0.022776573 | BJ3: Also must run wind, solar, geo min 60% | BR3: 2 | BS3: hours | BT3: 2.5 | BV3: lcoe | BW3: 98.9 | BX3: =(BW3-'0. Current system'!$G3)/'0. Current system'!$G3 -> -0.45956284 | BY3: =(BW3-'1. Diesel, no storage'!$G3)/'1. Diesel, no storage'!$G3 -> -0.16820858 | BZ3: =(BW3-$G3)/$G3 -> 0.072668113 | CB3: Also must run wind, solar, geo min 60% | CJ3: 6 | CK3: hours | CL3: 2.6 | CN3: lcoe | CO3: 91.9 | CP3: =(CO3-'0. Current system'!$G3)/'0. Current system'!$G3 -> -0.49781421 | CQ3: =(CO3-'1. Diesel, no storage'!$G3)/'1. Diesel, no storage'!$G3 -> -0.22708158 | CR3: =(CO3-$G3)/$G3 -> -0.0032537961 | CT3: Also must run wind, solar, geo min 60% | CX3: 8 | CY3: hours | DB3: lcoe | DC3: 91.8 | DD3: =(DC3-'0. Current system'!$G3)/'0. Current system'!$G3 -> -0.49836066 | DE3: =(DC3-'1. Diesel, no storage'!$G3)/'1. Diesel, no storage'!$G3 -> -0.22792262 | DF3: =(DC3-$G3)/$G3 -> -0.0043383948 | DH3: Also must run wind, solar, geo min 60%
B4: StorageUnit | D4: [MWh] | T4: StorageUnit | V4: [MWh] | X4: Country | Z4: compare to current system | AA4: compare to w/o storage | AB4: compare to baseline w/ storage | AL4: StorageUnit | AN4: [MWh] | AR4: compare to current system | AS4: compare to w/o storage | AT4: compare to baseline w/ storage | AZ4: StorageUnit | BB4: [MWh] | BD4: Country | BE4: $/MWh | BF4: compare to current system | BG4: compare to w/o storage | BH4: compare to baseline w/ storage | BR4: StorageUnit | BT4: [MWh] | BV4: Country | BW4: $/MWh | BX4: compare to current system | BY4: compare to w/o storage | BZ4: compare to baseline w/ storage | CJ4: StorageUnit | CL4: [MWh] | CN4: Country | CO4: $/MWh | CP4: compare to current system | CQ4: compare to w/o storage | CR4: compare to baseline w/ storage | CX4: StorageUnit | CZ4: [MWh] | DB4: Country | DC4: $/MWh | DD4: compare to current system | DE4: compare to w/o storage | DF4: compare to baseline w/ storage
B5: ATG Storage | C5: 70 | D5: =C5*B$3 -> 280 | F5: ATG | G5: 105.01968 | H5: =(G5-'0. Current system'!$G5)/'0. Current system'!$G5 -> -0.48040856 | I5: =(G5-'1. Diesel, no storage'!$G5)/'1. Diesel, no storage'!$G5 -> -0.23520733 | T5: ATG Storage | U5: 70 | V5: =U5*T$3 -> 280 | X5: ATG | Y5: 105.01968 | Z5: =(Y5-'0. Current system'!$G5)/'0. Current system'!$G5 -> -0.48040856 | AA5: =(Y5-'1. Diesel, no storage'!$G5)/'1. Diesel, no storage'!$G5 -> -0.23520733 | AB5: =(Y5-$G5)/$G5 -> 0 | AL5: ATG Storage | AM5: 70 | AN5: =AM5*AL$3 -> 280 | AP5: ATG | AQ5: 108.36755 | AR5: =(AQ5-'0. Current system'!$G5)/'0. Current system'!$G5 -> -0.46384479 | AS5: =(AQ5-'1. Diesel, no storage'!$G5)/'1. Diesel, no storage'!$G5 -> -0.21082693 | AT5: =(AQ5-$G5)/$G5 -> 0.031878444 | AZ5: ATG Storage | BA5: 70 | BB5: =BA5*AZ$3 -> 420 | BD5: ATG | BE5: 98.979073 | BF5: =(BE5-'0. Current system'!$G5)/'0. Current system'!$G5 -> -0.51029485 | BG5: =(BE5-'1. Diesel, no storage'!$G5)/'1. Diesel, no storage'!$G5 -> -0.2791973 | BH5: =(BE5-$G5)/$G5 -> -0.057518819 | BJ5: =BE5*BJ32 -> 43255.443 | BR5: ATG Storage | BS5: 70 | BT5: =BS5*BR$3 -> 140 | BV5: ATG | BW5: 113.05147 | BX5: =(BW5-'0. Current system'!$G5)/'0. Current system'!$G5 -> -0.44067077 | BY5: =(BW5-'1. Diesel, no storage'!$G5)/'1. Diesel, no storage'!$G5 -> -0.17671682 | BZ5: =(BW5-$G5)/$G5 -> 0.076478913 | CJ5: ATG Storage | CK5: 70 | CL5: =CK5*CJ$3 -> 420 | CN5: ATG | CO5: 98.979073 | CP5: =(CO5-'0. Current system'!$G5)/'0. Current system'!$G5 -> -0.51029485 | CQ5: =(CO5-'1. Diesel, no storage'!$G5)/'1. Diesel, no storage'!$G5 -> -0.2791973 | CR5: =(CO5-$G5)/$G5 -> -0.057518819 | CX5: TG Storage | CY5: 70 | CZ5: =CY5*CX$3 -> 560 | DB5: ATG | DC5: 97.638358 | DD5: =(DC5-'0. Current system'!$G5)/'0. Current system'!$G5 -> -0.51692812 | DE5: =(DC5-'1. Diesel, no storage'!$G5)/'1. Diesel, no storage'!$G5 -> -0.28896089 | DF5: =(DC5-$G5)/$G5 -> -0.07028514
B6: BRB Storage | C6: 200 | D6: =C6*B$3 -> 800 | F6: BRB | G6: 91.499505 | H6: =(G6-'0. Current system'!$G6)/'0. Current system'!$G6 -> -0.50418994 | I6: =(G6-'1. Diesel, no storage'!$G6)/'1. Diesel, no storage'!$G6 -> -0.26059565 | T6: BRB Storage | U6: 173.53875 | V6: =U6*T$3 -> 694.155 | X6: BRB | Y6: 100.82667 | Z6: =(Y6-'0. Current system'!$G6)/'0. Current system'!$G6 -> -0.45364869 | AA6: =(Y6-'1. Diesel, no storage'!$G6)/'1. Diesel, no storage'!$G6 -> -0.18522319 | AB6: =(Y6-$G6)/$G6 -> 0.10193673 | AL6: BRB Storage | AM6: 174.88342 | AN6: =AM6*AL$3 -> 699.53368 | AP6: BRB | AQ6: 94.926763 | AR6: =(AQ6-'0. Current system'!$G6)/'0. Current system'!$G6 -> -0.4856186 | AS6: =(AQ6-'1. Diesel, no storage'!$G6)/'1. Diesel, no storage'!$G6 -> -0.23290009 | AT6: =(AQ6-$G6)/$G6 -> 0.037456574 | AZ6: BRB Storage | BA6: 200 | BB6: =BA6*AZ$3 -> 1200 | BD6: BRB | BE6: 89.944397 | BF6: =(BE6-'0. Current system'!$G6)/'0. Current system'!$G6 -> -0.51261664 | BG6: =(BE6-'1. Diesel, no storage'!$G6)/'1. Diesel, no storage'!$G6 -> -0.27316242 | BH6: =(BE6-$G6)/$G6 -> -0.016995808 | BJ6: =BE6*BJ33 -> 108106.16 | BR6: BRB Storage | BS6: 200 | BT6: =BS6*BR$3 -> 400 | BV6: BRB | BW6: 112.3077 | BX6: =(BW6-'0. Current system'!$G6)/'0. Current system'!$G6 -> -0.39143617 | BY6: =(BW6-'1. Diesel, no storage'!$G6)/'1. Diesel, no storage'!$G6 -> -0.092445309 | BZ6: =(BW6-$G6)/$G6 -> 0.22741324 | CJ6: BRB Storage | CK6: 116.59333 | CL6: =CK6*CJ$3 -> 699.56 | CN6: BRB | CO6: 100.6393 | CP6: =(CO6-'0. Current system'!$G6)/'0. Current system'!$G6 -> -0.45466398 | CQ6: =(CO6-'1. Diesel, no storage'!$G6)/'1. Diesel, no storage'!$G6 -> -0.1867373 | CR6: =(CO6-$G6)/$G6 -> 0.099888988 | CX6: BRB Storage | CY6: 103.064 | CZ6: =CY6*CX$3 -> 824.512 | DB6: BRB | DC6: 101.65378 | DD6: =(DC6-'0. Current system'!$G6)/'0. Current system'!$G6 -> -0.4491668 | DE6: =(DC6-'1. Diesel, no storage'!$G6)/'1. Diesel, no storage'!$G6 -> -0.17853933 | DF6: =(DC6-$G6)/$G6 -> 0.11097625
B7: DMA Storage | C7: 0 | D7: =C7*B$3 -> 0 | F7: DMA | G7: 111.5797 | H7: =(G7-'0. Current system'!$G7)/'0. Current system'!$G7 -> -0.1341537 | I7: =(G7-'1. Diesel, no storage'!$G7)/'1. Diesel, no storage'!$G7 -> 0 | T7: DMA Storage | U7: 0 | V7: =U7*T$3 -> 0 | X7: DMA | Y7: 111.5797 | Z7: =(Y7-'0. Current system'!$G7)/'0. Current system'!$G7 -> -0.1341537 | AA7: =(Y7-'1. Diesel, no storage'!$G7)/'1. Diesel, no storage'!$G7 -> 0 | AB7: =(Y7-$G7)/$G7 -> 0 | AL7: DMA Storage | AM7: 0 | AN7: =AM7*AL$3 -> 0 | AP7: DMA | AQ7: 111.5797 | AR7: =(AQ7-'0. Current system'!$G7)/'0. Current system'!$G7 -> -0.1341537 | AS7: =(AQ7-'1. Diesel, no storage'!$G7)/'1. Diesel, no storage'!$G7 -> 0 | AT7: =(AQ7-$G7)/$G7 -> 0 | AZ7: DMA Storage | BA7: 0 | BB7: =BA7*AZ$3 -> 0 | BD7: DMA | BE7: 111.5797 | BF7: =(BE7-'0. Current system'!$G7)/'0. Current system'!$G7 -> -0.1341537 | BG7: =(BE7-'1. Diesel, no storage'!$G7)/'1. Diesel, no storage'!$G7 -> 0 | BH7: =(BE7-$G7)/$G7 -> 0 | BJ7: =BE7*BJ34 -> 14224.281 | BR7: DMA Storage | BS7: 0 | BT7: =BS7*BR$3 -> 0 | BV7: DMA | BW7: 111.5797 | BX7: =(BW7-'0. Current system'!$G7)/'0. Current system'!$G7 -> -0.1341537 | BY7: =(BW7-'1. Diesel, no storage'!$G7)/'1. Diesel, no storage'!$G7 -> 0 | BZ7: =(BW7-$G7)/$G7 -> 0 | CJ7: DMA Storage | CK7: 0 | CL7: =CK7*CJ$3 -> 0 | CN7: DMA | CO7: 111.5797 | CP7: =(CO7-'0. Current system'!$G7)/'0. Current system'!$G7 -> -0.1341537 | CQ7: =(CO7-'1. Diesel, no storage'!$G7)/'1. Diesel, no storage'!$G7 -> 0 | CR7: =(CO7-$G7)/$G7 -> 0 | CX7: DMA Storage | CY7: 0 | CZ7: =CY7*CX$3 -> 0 | DB7: DMA | DC7: 111.5797 | DD7: =(DC7-'0. Current system'!$G7)/'0. Current system'!$G7 -> -0.1341537 | DE7: =(DC7-'1. Diesel, no storage'!$G7)/'1. Diesel, no storage'!$G7 -> 0 | DF7: =(DC7-$G7)/$G7 -> 0
B8: GLP Storage | C8: 320 | D8: =C8*B$3 -> 1280 | F8: GLP | G8: 89.592667 | H8: =(G8-'0. Current system'!$G8)/'0. Current system'!$G8 -> -0.47828212 | I8: =(G8-'1. Diesel, no storage'!$G8)/'1. Diesel, no storage'!$G8 -> -0.23276049 | T8: GLP Storage | U8: 320 | V8: =U8*T$3 -> 1280 | X8: GLP | Y8: 89.592667 | Z8: =(Y8-'0. Current system'!$G8)/'0. Current system'!$G8 -> -0.47828212 | AA8: =(Y8-'1. Diesel, no storage'!$G8)/'1. Diesel, no storage'!$G8 -> -0.23276049 | AB8: =(Y8-$G8)/$G8 -> 0 | AL8: GLP Storage | AM8: 320 | AN8: =AM8*AL$3 -> 1280 | AP8: GLP | AQ8: 92.931534 | AR8: =(AQ8-'0. Current system'!$G8)/'0. Current system'!$G8 -> -0.45883916 | AS8: =(AQ8-'1. Diesel, no storage'!$G8)/'1. Diesel, no storage'!$G8 -> -0.20416763 | AT8: =(AQ8-$G8)/$G8 -> 0.037267191 | AZ8: GLP Storage | BA8: 320 | BB8: =BA8*AZ$3 -> 1920 | BD8: GLP | BE8: 86.999076 | BF8: =(BE8-'0. Current system'!$G8)/'0. Current system'!$G8 -> -0.49338517 | BG8: =(BE8-'1. Diesel, no storage'!$G8)/'1. Diesel, no storage'!$G8 -> -0.25497107 | BH8: =(BE8-$G8)/$G8 -> -0.028948697 | BJ8: =BE8*BJ35 -> 174273.96 | BR8: GLP Storage | BS8: 320 | BT8: =BS8*BR$3 -> 640 | BV8: GLP | BW8: 94.058183 | BX8: =(BW8-'0. Current system'!$G8)/'0. Current system'!$G8 -> -0.45227843 | BY8: =(BW8-'1. Diesel, no storage'!$G8)/'1. Diesel, no storage'!$G8 -> -0.19451941 | BZ8: =(BW8-$G8)/$G8 -> 0.049842427 | CJ8: GLP Storage | CK8: 320 | CL8: =CK8*CJ$3 -> 1920 | CN8: GLP | CO8: 86.999076 | CP8: =(CO8-'0. Current system'!$G8)/'0. Current system'!$G8 -> -0.49338517 | CQ8: =(CO8-'1. Diesel, no storage'!$G8)/'1. Diesel, no storage'!$G8 -> -0.25497107 | CR8: =(CO8-$G8)/$G8 -> -0.028948697 | CX8: GLP Storage | CY8: 320 | CZ8: =CY8*CX$3 -> 2560 | DB8: GLP | DC8: 86.725031 | DD8: =(DC8-'0. Current system'!$G8)/'0. Current system'!$G8 -> -0.494981 | DE8: =(DC8-'1. Diesel, no storage'!$G8)/'1. Diesel, no storage'!$G8 -> -0.2573179 | DF8: =(DC8-$G8)/$G8 -> -0.032007486
B9: GRD Storage | C9: 45 | D9: =C9*B$3 -> 180 | F9: GRD | G9: 91.988956 | H9: =(G9-'0. Current system'!$G9)/'0. Current system'!$G9 -> -0.54384289 | I9: =(G9-'1. Diesel, no storage'!$G9)/'1. Diesel, no storage'!$G9 -> -0.22809329 | T9: GRD Storage | U9: 45 | V9: =U9*T$3 -> 180 | X9: GRD | Y9: 91.988956 | Z9: =(Y9-'0. Current system'!$G9)/'0. Current system'!$G9 -> -0.54384289 | AA9: =(Y9-'1. Diesel, no storage'!$G9)/'1. Diesel, no storage'!$G9 -> -0.22809329 | AB9: =(Y9-$G9)/$G9 -> 0 | AL9: GRD Storage | AM9: 40.292891 | AN9: =AM9*AL$3 -> 161.17156 | AP9: GRD | AQ9: 95.436862 | AR9: =(AQ9-'0. Current system'!$G9)/'0. Current system'!$G9 -> -0.52674533 | AS9: =(AQ9-'1. Diesel, no storage'!$G9)/'1. Diesel, no storage'!$G9 -> -0.19916089 | AT9: =(AQ9-$G9)/$G9 -> 0.037481739 | AZ9: GRD Storage | BA9: 33.471216 | BB9: =BA9*AZ$3 -> 200.8273 | BD9: GRD | BE9: 91.612383 | BF9: =(BE9-'0. Current system'!$G9)/'0. Current system'!$G9 -> -0.54571025 | BG9: =(BE9-'1. Diesel, no storage'!$G9)/'1. Diesel, no storage'!$G9 -> -0.23125323 | BH9: =(BE9-$G9)/$G9 -> -0.0040936762 | BJ9: =BE9*BJ36 -> 24187.382 | BR9: GRD Storage | BS9: 45 | BT9: =BS9*BR$3 -> 90 | BV9: GRD | BW9: 95.695962 | BX9: =(BW9-'0. Current system'!$G9)/'0. Current system'!$G9 -> -0.5254605 | BY9: =(BW9-'1. Diesel, no storage'!$G9)/'1. Diesel, no storage'!$G9 -> -0.1969867 | BZ9: =(BW9-$G9)/$G9 -> 0.040298381 | CJ9: GRD Storage | CK9: 33.471216 | CL9: =CK9*CJ$3 -> 200.8273 | CN9: GRD | CO9: 91.612383 | CP9: =(CO9-'0. Current system'!$G9)/'0. Current system'!$G9 -> -0.54571025 | CQ9: =(CO9-'1. Diesel, no storage'!$G9)/'1. Diesel, no storage'!$G9 -> -0.23125323 | CR9: =(CO9-$G9)/$G9 -> -0.0040936762 | CX9: GRD Storage | CY9: 25.273246 | CZ9: =CY9*CX$3 -> 202.18597 | DB9: GRD | DC9: 91.516062 | DD9: =(DC9-'0. Current system'!$G9)/'0. Current system'!$G9 -> -0.54618789 | DE9: =(DC9-'1. Diesel, no storage'!$G9)/'1. Diesel, no storage'!$G9 -> -0.23206149 | DF9: =(DC9-$G9)/$G9 -> -0.0051407693
B10: LCA Storage | C10: 75 | D10: =C10*B$3 -> 300 | F10: LCA | G10: 95.272126 | H10: =(G10-'0. Current system'!$G10)/'0. Current system'!$G10 -> -0.52715088 | I10: =(G10-'1. Diesel, no storage'!$G10)/'1. Diesel, no storage'!$G10 -> -0.19661871 | T10: LCA Storage | U10: 75 | V10: =U10*T$3 -> 300 | X10: LCA | Y10: 95.272126 | Z10: =(Y10-'0. Current system'!$G10)/'0. Current system'!$G10 -> -0.52715088 | AA10: =(Y10-'1. Diesel, no storage'!$G10)/'1. Diesel, no storage'!$G10 -> -0.19661871 | AB10: =(Y10-$G10)/$G10 -> 0 | AL10: LCA Storage | AM10: 69.741106 | AN10: =AM10*AL$3 -> 278.96442 | AP10: LCA | AQ10: 98.579589 | AR10: =(AQ10-'0. Current system'!$G10)/'0. Current system'!$G10 -> -0.51073547 | AS10: =(AQ10-'1. Diesel, no storage'!$G10)/'1. Diesel, no storage'!$G10 -> -0.16872856 | AT10: =(AQ10-$G10)/$G10 -> 0.034715957 | AZ10: LCA Storage | BA10: 75 | BB10: =BA10*AZ$3 -> 450 | BD10: LCA | BE10: 93.501378 | BF10: =(BE10-'0. Current system'!$G10)/'0. Current system'!$G10 -> -0.53593935 | BG10: =(BE10-'1. Diesel, no storage'!$G10)/'1. Diesel, no storage'!$G10 -> -0.21155053 | BH10: =(BE10-$G10)/$G10 -> -0.018586213 | BJ10: =BE10*BJ37 -> 44267.236 | BR10: LCA Storage | BS10: 75 | BT10: =BS10*BR$3 -> 150 | BV10: LCA | BW10: 97.349355 | BX10: =(BW10-'0. Current system'!$G10)/'0. Current system'!$G10 -> -0.51684129 | BY10: =(BW10-'1. Diesel, no storage'!$G10)/'1. Diesel, no storage'!$G10 -> -0.1791025 | BZ10: =(BW10-$G10)/$G10 -> 0.021803114 | CJ10: LCA Storage | CK10: 75 | CL10: =CK10*CJ$3 -> 450 | CN10: LCA | CO10: 93.501378 | CP10: =(CO10-'0. Current system'!$G10)/'0. Current system'!$G10 -> -0.53593935 | CQ10: =(CO10-'1. Diesel, no storage'!$G10)/'1. Diesel, no storage'!$G10 -> -0.21155053 | CR10: =(CO10-$G10)/$G10 -> -0.018586213 | CX10: LCA Storage | CY10: 75 | CZ10: =CY10*CX$3 -> 600 | DB10: LCA | DC10: 93.018536 | DD10: =(DC10-'0. Current system'!$G10)/'0. Current system'!$G10 -> -0.53833576 | DE10: =(DC10-'1. Diesel, no storage'!$G10)/'1. Diesel, no storage'!$G10 -> -0.21562209 | DF10: =(DC10-$G10)/$G10 -> -0.023654243
B11: MSR Storage | C11: 1.081209 | D11: =C11*B$3 -> 4.324836 | F11: MSR | G11: 105.92799 | H11: =(G11-'0. Current system'!$G11)/'0. Current system'!$G11 -> -0.44599551 | I11: =(G11-'1. Diesel, no storage'!$G11)/'1. Diesel, no storage'!$G11 -> -0.18026359 | T11: MSR Storage | U11: 1.081209 | V11: =U11*T$3 -> 4.324836 | X11: MSR | Y11: 105.92799 | Z11: =(Y11-'0. Current system'!$G11)/'0. Current system'!$G11 -> -0.44599551 | AA11: =(Y11-'1. Diesel, no storage'!$G11)/'1. Diesel, no storage'!$G11 -> -0.18026359 | AB11: =(Y11-$G11)/$G11 -> 0 | AL11: MSR Storage | AM11: 0.898598 | AN11: =AM11*AL$3 -> 3.594392 | AP11: MSR | AQ11: 107.19638 | AR11: =(AQ11-'0. Current system'!$G11)/'0. Current system'!$G11 -> -0.43936178 | AS11: =(AQ11-'1. Diesel, no storage'!$G11)/'1. Diesel, no storage'!$G11 -> -0.17044795 | AT11: =(AQ11-$G11)/$G11 -> 0.011974144 | AZ11: MSR Storage | BA11: 0.728178 | BB11: =BA11*AZ$3 -> 4.369068 | BD11: MSR | BE11: 105.84242 | BF11: =(BE11-'0. Current system'!$G11)/'0. Current system'!$G11 -> -0.44644302 | BG11: =(BE11-'1. Diesel, no storage'!$G11)/'1. Diesel, no storage'!$G11 -> -0.18092576 | BH11: =(BE11-$G11)/$G11 -> -0.0008077752 | BJ11: =BE11*BJ38 -> 1734.8123 | BR11: MSR Storage | BS11: 2.162418 | BT11: =BS11*BR$3 -> 4.324836 | BV11: MSR | BW11: 105.98016 | BX11: =(BW11-'0. Current system'!$G11)/'0. Current system'!$G11 -> -0.44572262 | BY11: =(BW11-'1. Diesel, no storage'!$G11)/'1. Diesel, no storage'!$G11 -> -0.17985981 | BZ11: =(BW11-$G11)/$G11 -> 0.00049257993 | CJ11: MSR Storage | CK11: 0.728178 | CL11: =CK11*CJ$3 -> 4.369068 | CN11: MSR | CO11: 105.84242 | CP11: =(CO11-'0. Current system'!$G11)/'0. Current system'!$G11 -> -0.44644302 | CQ11: =(CO11-'1. Diesel, no storage'!$G11)/'1. Diesel, no storage'!$G11 -> -0.18092576 | CR11: =(CO11-$G11)/$G11 -> -0.0008077752 | CX11: MSR Storage | CY11: 0.587846 | CZ11: =CY11*CX$3 -> 4.702768 | DB11: MSR | DC11: 105.91276 | DD11: =(DC11-'0. Current system'!$G11)/'0. Current system'!$G11 -> -0.44607516 | DE11: =(DC11-'1. Diesel, no storage'!$G11)/'1. Diesel, no storage'!$G11 -> -0.18038145 | DF11: =(DC11-$G11)/$G11 -> -0.00014376748
B12: MTQ Storage | C12: 250 | D12: =C12*B$3 -> 1000 | F12: MTQ | G12: 92.831085 | H12: =(G12-'0. Current system'!$G12)/'0. Current system'!$G12 -> -0.50011296 | I12: =(G12-'1. Diesel, no storage'!$G12)/'1. Diesel, no storage'!$G12 -> -0.21828102 | T12: MTQ Storage | U12: 250 | V12: =U12*T$3 -> 1000 | X12: MTQ | Y12: 92.831085 | Z12: =(Y12-'0. Current system'!$G12)/'0. Current system'!$G12 -> -0.50011296 | AA12: =(Y12-'1. Diesel, no storage'!$G12)/'1. Diesel, no storage'!$G12 -> -0.21828102 | AB12: =(Y12-$G12)/$G12 -> 0 | AL12: MTQ Storage | AM12: 250 | AN12: =AM12*AL$3 -> 1000 | AP12: MTQ | AQ12: 95.700409 | AR12: =(AQ12-'0. Current system'!$G12)/'0. Current system'!$G12 -> -0.4846619 | AS12: =(AQ12-'1. Diesel, no storage'!$G12)/'1. Diesel, no storage'!$G12 -> -0.1941188 | AT12: =(AQ12-$G12)/$G12 -> 0.030909086 | AZ12: MTQ Storage | BA12: 250 | BB12: =BA12*AZ$3 -> 1500 | BD12: MTQ | BE12: 91.054397 | BF12: =(BE12-'0. Current system'!$G12)/'0. Current system'!$G12 -> -0.50968026 | BG12: =(BE12-'1. Diesel, no storage'!$G12)/'1. Diesel, no storage'!$G12 -> -0.23324229 | BH12: =(BE12-$G12)/$G12 -> -0.019138934 | BJ12: =BE12*BJ39 -> 165816.73 | BR12: MTQ Storage | BS12: 250 | BT12: =BS12*BR$3 -> 500 | BV12: MTQ | BW12: 95.66139 | BX12: =(BW12-'0. Current system'!$G12)/'0. Current system'!$G12 -> -0.48487202 | BY12: =(BW12-'1. Diesel, no storage'!$G12)/'1. Diesel, no storage'!$G12 -> -0.19444737 | BZ12: =(BW12-$G12)/$G12 -> 0.030488764 | CJ12: MTQ Storage | CK12: 250 | CL12: =CK12*CJ$3 -> 1500 | CN12: MTQ | CO12: 91.054397 | CP12: =(CO12-'0. Current system'!$G12)/'0. Current system'!$G12 -> -0.50968026 | CQ12: =(CO12-'1. Diesel, no storage'!$G12)/'1. Diesel, no storage'!$G12 -> -0.23324229 | CR12: =(CO12-$G12)/$G12 -> -0.019138934 | CX12: MTQ Storage | CY12: 248.61855 | CZ12: =CY12*CX$3 -> 1988.9484 | DB12: MTQ | DC12: 90.435182 | DD12: =(DC12-'0. Current system'!$G12)/'0. Current system'!$G12 -> -0.51301468 | DE12: =(DC12-'1. Diesel, no storage'!$G12)/'1. Diesel, no storage'!$G12 -> -0.23845662 | DF12: =(DC12-$G12)/$G12 -> -0.025809275
B13: SKN Storage | C13: 45 | D13: =C13*B$3 -> 180 | F13: SKN | G13: 101.10778 | H13: =(G13-'0. Current system'!$G13)/'0. Current system'!$G13 -> -0.48905822 | I13: =(G13-'1. Diesel, no storage'!$G13)/'1. Diesel, no storage'!$G13 -> -0.1725235 | T13: SKN Storage | U13: 45 | V13: =U13*T$3 -> 180 | X13: SKN | Y13: 101.10778 | Z13: =(Y13-'0. Current system'!$G13)/'0. Current system'!$G13 -> -0.48905822 | AA13: =(Y13-'1. Diesel, no storage'!$G13)/'1. Diesel, no storage'!$G13 -> -0.1725235 | AB13: =(Y13-$G13)/$G13 -> 0 | AL13: SKN Storage | AM13: 45 | AN13: =AM13*AL$3 -> 180 | AP13: SKN | AQ13: 104.55069 | AR13: =(AQ13-'0. Current system'!$G13)/'0. Current system'!$G13 -> -0.47165967 | AS13: =(AQ13-'1. Diesel, no storage'!$G13)/'1. Diesel, no storage'!$G13 -> -0.14434634 | AT13: =(AQ13-$G13)/$G13 -> 0.03405192 | AZ13: SKN Storage | BA13: 45 | BB13: =BA13*AZ$3 -> 270 | BD13: SKN | BE13: 99.186918 | BF13: =(BE13-'0. Current system'!$G13)/'0. Current system'!$G13 -> -0.49876517 | BG13: =(BE13-'1. Diesel, no storage'!$G13)/'1. Diesel, no storage'!$G13 -> -0.18824404 | BH13: =(BE13-$G13)/$G13 -> -0.018998162 | BJ13: =BE13*BJ40 -> 27096.165 | BR13: SKN Storage | BS13: 45 | BT13: =BS13*BR$3 -> 90 | BV13: SKN | BW13: 104.65667 | BX13: =(BW13-'0. Current system'!$G13)/'0. Current system'!$G13 -> -0.47112411 | BY13: =(BW13-'1. Diesel, no storage'!$G13)/'1. Diesel, no storage'!$G13 -> -0.143479 | BZ13: =(BW13-$G13)/$G13 -> 0.035100098 | CJ13: SKN Storage | CK13: 45 | CL13: =CK13*CJ$3 -> 270 | CN13: SKN | CO13: 99.186918 | CP13: =(CO13-'0. Current system'!$G13)/'0. Current system'!$G13 -> -0.49876517 | CQ13: =(CO13-'1. Diesel, no storage'!$G13)/'1. Diesel, no storage'!$G13 -> -0.18824404 | CR13: =(CO13-$G13)/$G13 -> -0.018998162 | CX13: SKN Storage | CY13: 38.037964 | CZ13: =CY13*CX$3 -> 304.30371 | DB13: SKN | DC13: 99.414418 | DD13: =(DC13-'0. Current system'!$G13)/'0. Current system'!$G13 -> -0.49761551 | DE13: =(DC13-'1. Diesel, no storage'!$G13)/'1. Diesel, no storage'!$G13 -> -0.18638215 | DF13: =(DC13-$G13)/$G13 -> -0.016748088
